Workbook

Sheet CRIA FASE 1
A1: Parâmetros | B1: Selecione ou preencha
A2: Name
A3: Interface binding
A4: ike-version
A5: remote-gw
A6: local-gw
A7: nattraversal
A8: keylife
A9: proposal
A10: psksecret
A11: dhgrp
B12: SCRIPT FASE 1
B13: =IF(B2=""," ",CONCATENATE("config vpn ipsec phase1-interface"))
B14: =IF(B2=""," ",CONCATENATE("edit ",B2))
B15: =IF(B3=""," ",CONCATENATE("set interface ",B3))
B16: =IF(B4=""," ",CONCATENATE("set ike-version ",B4))
B17: =IF(B5=""," ",CONCATENATE("set remote-gw ",B5))
B18: =IF(B6=""," ",CONCATENATE("set local-gw ",B6))
B19: =IF(B7=""," ",CONCATENATE("set nattraversal ",B7))
B20: =IF(B8=""," ",CONCATENATE("set keylife ",B8))
B21: =IF(B9=""," ",CONCATENATE("set proposal ",B9))
B22: =IF(B10=""," ",CONCATENATE("set psksecret ",B10))
B23: =IF(B11=""," ",CONCATENATE("set dhgrp ",B11))
B24: =IF(B2=""," ",CONCATENATE("end"))
B116: portas | C116: ike | D116: nat_transversal | E116: grupo DH | F116: proposal
B117: internal1 | C117: 1 | D117: enable | E117: 1 | F117: des-md5
B118: internal2 | C118: 2 | D118: disable | E118: 2 | F118: des-sha1
B119: internal3 | E119: 5 | F119: des-sha256
B120: internal4 | E120: 14 | F120: des-sha384
B121: internal5 | E121: 15 | F121: des-sha512
B122: internal6 | E122: 16 | F122: 3des-md5
B123: internal7 | E123: 17 | F123: 3des-sha1
B124: internal8 | E124: 18 | F124: 3des-sha256
B125: internal9 | E125: 19 | F125: 3des-sha384
B126: internal10 | E126: 20 | F126: 3des-sha512
B127: internal11 | E127: 21 | F127: aes128-md5
B128: internal12 | F128: aes128-sha1
B129: internal13 | F129: aes128-sha256
B130: internal14 | F130: aes128-sha384
B131: internal15 | F131: aes128-sha512
...

Sheet CRIA OBJETOS
F1: SCRIPT OBJETOS LOCAIS | G1: SCRIPT OBJETOS REMOTOS | H1: SCRIPT GRUPO LOCAL | I1: SCRIPT GRUPO REMOTO
A2: REDES LOCAIS | B2: REDES REMOTAS | F2: =IF(A3=""," ",CONCATENATE("config firewall address")) | G2: =IF(B3=""," ",CONCATENATE("config firewall address")) | H2: =IF(A3=""," ",CONCATENATE("config firewall addrgrp")) | I2: =IF(B3=""," ",CONCATENATE("config firewall addrgrp"))
F3: =IF(A3=""," ",CONCATENATE("edit LOCALNET_",A3)) | G3: =IF(B3=""," ",CONCATENATE("edit REMOTENET_",B3)) | H3: =IF(A3=""," ",CONCATENATE("edit Local_proxy_id_",'CRIA FASE 1'!B2)) | I3: =IF(B3=""," ",CONCATENATE("edit Remote_proxy_id_",'CRIA FASE 1'!B2))
F4: =IF(A3=""," ",CONCATENATE("set subnet ",A3)) | G4: =IF(B3=""," ",CONCATENATE("set associated-interface ",'CRIA FASE 1'!B2)) | H4: set member ***** | I4: set member *****
F5: =IF(A3=""," ",CONCATENATE("end")) | G5: =IF(B3=""," ",CONCATENATE("set subnet ",B3)) | H5: =IF(A3=""," ",CONCATENATE("end")) | I5: =IF(B3=""," ",CONCATENATE("end"))
F6: =IF(A4=""," ",CONCATENATE("config firewall address")) | G6: =IF(B3=""," ",CONCATENATE("end"))
F7: =IF(A4=""," ",CONCATENATE("edit LOCALNET_",A4)) | G7: =IF(B4=""," ",CONCATENATE("config firewall address"))
F8: =IF(A4=""," ",CONCATENATE("set subnet ",A4)) | G8: =IF(B4=""," ",CONCATENATE("edit REMOTENET_",B4))
F9: =IF(A4=""," ",CONCATENATE("end")) | G9: =IF(B4=""," ",CONCATENATE("set associated-interface ",'CRIA FASE 1'!B2))
F10: =IF(A5=""," ",CONCATENATE("config firewall address")) | G10: =IF(B4=""," ",CONCATENATE("set subnet ",B4))
F11: =IF(A5=""," ",CONCATENATE("edit LOCALNET_",A5)) | G11: =IF(B4=""," ",CONCATENATE("end"))
F12: =IF(A5=""," ",CONCATENATE("set subnet ",A5)) | G12: =IF(B5=""," ",CONCATENATE("config firewall address"))
F13: =IF(A5=""," ",CONCATENATE("end")) | G13: =IF(B5=""," ",CONCATENATE("edit REMOTENET_",B5))
F14: =IF(A6=""," ",CONCATENATE("config firewall address")) | G14: =IF(B5=""," ",CONCATENATE("set associated-interface ",'CRIA FASE 1'!B2))
F15: =IF(A6=""," ",CONCATENATE("edit LOCALNET_",A6)) | G15: =IF(B5=""," ",CONCATENATE("set subnet ",B5))
F16: =IF(A6=""," ",CONCATENATE("set subnet ",A6)) | G16: =IF(B5=""," ",CONCATENATE("end"))
F17: =IF(A6=""," ",CONCATENATE("end")) | G17: =IF(B6=""," ",CONCATENATE("config firewall address"))
F18: =IF(A7=""," ",CONCATENATE("config firewall address")) | G18: =IF(B6=""," ",CONCATENATE("edit REMOTENET_",B6))
F19: =IF(A7=""," ",CONCATENATE("edit LOCALNET_",A7)) | G19: =IF(B6=""," ",CONCATENATE("set associated-interface ",'CRIA FASE 1'!B2))
F20: =IF(A7=""," ",CONCATENATE("set subnet ",A7)) | G20: =IF(B6=""," ",CONCATENATE("set subnet ",B6))
F21: =IF(A7=""," ",CONCATENATE("end")) | G21: =IF(B6=""," ",CONCATENATE("end"))
F22: =IF(A8=""," ",CONCATENATE("config firewall address")) | G22: =IF(B7=""," ",CONCATENATE("config firewall address"))
F23: =IF(A8=""," ",CONCATENATE("edit LOCALNET_",A8)) | G23: =IF(B7=""," ",CONCATENATE("edit REMOTENET_",B7))
F24: =IF(A8=""," ",CONCATENATE("set subnet ",A8)) | G24: =IF(B7=""," ",CONCATENATE("set associated-interface ",'CRIA FASE 1'!B2))
F25: =IF(A8=""," ",CONCATENATE("end")) | G25: =IF(B7=""," ",CONCATENATE("set subnet ",B7))
F26: =IF(A9=""," ",CONCATENATE("config firewall address")) | G26: =IF(B7=""," ",CONCATENATE("end"))
F27: =IF(A9=""," ",CONCATENATE("edit LOCALNET_",A9)) | G27: =IF(B8=""," ",CONCATENATE("config firewall address"))
F28: =IF(A9=""," ",CONCATENATE("set subnet ",A9)) | G28: =IF(B8=""," ",CONCATENATE("edit REMOTENET_",B8))
F29: =IF(A9=""," ",CONCATENATE("end")) | G29: =IF(B8=""," ",CONCATENATE("set associated-interface ",'CRIA FASE 1'!B2))
F30: =IF(A10=""," ",CONCATENATE("config firewall address")) | G30: =IF(B8=""," ",CONCATENATE("set subnet ",B8))
F31: =IF(A10=""," ",CONCATENATE("edit LOCALNET_",A10)) | G31: =IF(B8=""," ",CONCATENATE("end"))
F32: =IF(A10=""," ",CONCATENATE("set associated-interface any")) | G32: =IF(B9=""," ",CONCATENATE("config firewall address"))
F33: =IF(A10=""," ",CONCATENATE("set subnet ",A10)) | G33: =IF(B9=""," ",CONCATENATE("edit REMOTENET_",B9))
F34: =IF(A10=""," ",CONCATENATE("end")) | G34: =IF(B9=""," ",CONCATENATE("set associated-interface ",'CRIA FASE 1'!B2))
F35: =IF(A11=""," ",CONCATENATE("config firewall address")) | G35: =IF(B9=""," ",CONCATENATE("set subnet ",B9))
F36: =IF(A11=""," ",CONCATENATE("edit LOCALNET_",A11)) | G36: =IF(B9=""," ",CONCATENATE("end"))
F37: =IF(A11=""," ",CONCATENATE("set subnet ",A11)) | G37: =IF(B10=""," ",CONCATENATE("config firewall address"))
F38: =IF(A11=""," ",CONCATENATE("end")) | G38: =IF(B10=""," ",CONCATENATE("edit REMOTENET_",B10))
F39: =IF(A12=""," ",CONCATENATE("config firewall address")) | G39: =IF(B10=""," ",CONCATENATE("set associated-interface ",'CRIA FASE 1'!B2))
F40: =IF(A12=""," ",CONCATENATE("edit LOCALNET_",A12)) | G40: =IF(B10=""," ",CONCATENATE("set subnet ",B10))
...

Sheet CRIA FASE 2
A1: Parâmetros | B1: Selecione ou preencha
A2: Keepalive
A3: PFS
A4: =IF(B3="disable"," ",CONCATENATE("DHGRP")) -> DHGRP
A5: keylifeseconds
A6: Proposal
F10: SCRIPT
F11: =IF(B2=""," ","config vpn ipsec phase2-interface")
F12: =IF(B2=""," ",CONCATENATE("edit ",'CRIA FASE 1'!B2,"_P2_1"))
F13: =IF(B2=""," ",CONCATENATE("set phase1name ",'CRIA FASE 1'!B2,""))
F14: =IF(B2=""," ",CONCATENATE("set keepalive ",B2,""))
F15: =IF(B3=""," ",CONCATENATE("set pfs ",B3,""))
F16: =IF(B3="disable"," ",CONCATENATE("set dhgrp ",B4,"")) -> set dhgrp
F17: =IF(B5=""," ",CONCATENATE("set keylifeseconds ",B5,""))
F18: =IF(B2=""," ",CONCATENATE("set src-addr-type name"))
F19: =IF(B2=""," ",CONCATENATE("set dst-addr-type name"))
F20: =IF(B2=""," ",CONCATENATE("set proposal ",B6,""))
F21: =IF(B2=""," ",CONCATENATE("set src-name Local_proxy_id_",'CRIA FASE 1'!B2,""))
F22: =IF(B2=""," ",CONCATENATE("set dst-name Remote_proxy_id_",'CRIA FASE 1'!B2,""))
F23: =IF(B2=""," ",CONCATENATE("end"))
B73: keep_alive | C73: PFS | D73: grupo DH | E73: proposal
B74: enable | C74: enable | D74: 1 | E74: des-md5
B75: disable | C75: disable | D75: 2 | E75: des-sha1
D76: 5 | E76: des-sha256
D77: 14 | E77: des-sha384
D78: 15 | E78: des-sha512
D79: 16 | E79: 3des-md5
D80: 17 | E80: 3des-sha1
D81: 18 | E81: 3des-sha256
D82: 19 | E82: 3des-sha384
D83: 20 | E83: 3des-sha512
D84: 21 | E84: aes128-md5
E85: aes128-sha1
E86: aes128-sha256
E87: aes128-sha384
E88: aes128-sha512
E89: aes192-md5
E90: aes192-sha1
E91: aes192-sha256
E92: aes192-sha384
...

Sheet CRIA ROTAS
A1: SCRIPT
A2: =IF('CRIA OBJETOS'!B3=""," ",CONCATENATE("config router static"))
A3: =IF('CRIA OBJETOS'!B3=""," ",CONCATENATE("edit 0"))
A4: =IF('CRIA OBJETOS'!B3=""," ",CONCATENATE("set dst ",'CRIA OBJETOS'!B3))
A5: =IF('CRIA OBJETOS'!B3=""," ",CONCATENATE("set device ",'CRIA FASE 1'!B2))
A6: =IF('CRIA OBJETOS'!B3=""," ",CONCATENATE("set comment ",'CRIA FASE 1'!B2))
A7: =IF('CRIA OBJETOS'!B3=""," ",CONCATENATE("end"))
A8: =IF('CRIA OBJETOS'!B4=""," ",CONCATENATE("config router static"))
A9: =IF('CRIA OBJETOS'!B4=""," ",CONCATENATE("edit 0"))
A10: =IF('CRIA OBJETOS'!B4=""," ",CONCATENATE("set dst ",'CRIA OBJETOS'!B4))
A11: =IF('CRIA OBJETOS'!B4=""," ",CONCATENATE("set device ",'CRIA FASE 1'!B2))
A12: =IF('CRIA OBJETOS'!B4=""," ",CONCATENATE("set comment ",'CRIA FASE 1'!B2))
A13: =IF('CRIA OBJETOS'!B4=""," ",CONCATENATE("end"))
A14: =IF('CRIA OBJETOS'!B5=""," ",CONCATENATE("config router static"))
A15: =IF('CRIA OBJETOS'!B5=""," ",CONCATENATE("edit 0"))
A16: =IF('CRIA OBJETOS'!B5=""," ",CONCATENATE("set dst ",'CRIA OBJETOS'!B5))
A17: =IF('CRIA OBJETOS'!B5=""," ",CONCATENATE("set device ",'CRIA FASE 1'!B2))
A18: =IF('CRIA OBJETOS'!B5=""," ",CONCATENATE("set comment ",'CRIA FASE 1'!B2))
A19: =IF('CRIA OBJETOS'!B5=""," ",CONCATENATE("end"))
A20: =IF('CRIA OBJETOS'!B6=""," ",CONCATENATE("config router static"))
A21: =IF('CRIA OBJETOS'!B6=""," ",CONCATENATE("edit 0"))
A22: =IF('CRIA OBJETOS'!B6=""," ",CONCATENATE("set dst ",'CRIA OBJETOS'!B6))
A23: =IF('CRIA OBJETOS'!B6=""," ",CONCATENATE("set device ",'CRIA FASE 1'!B2))
A24: =IF('CRIA OBJETOS'!B6=""," ",CONCATENATE("set comment ",'CRIA FASE 1'!B2))
A25: =IF('CRIA OBJETOS'!B6=""," ",CONCATENATE("end"))
A26: =IF('CRIA OBJETOS'!B7=""," ",CONCATENATE("config router static"))
A27: =IF('CRIA OBJETOS'!B7=""," ",CONCATENATE("edit 0"))
A28: =IF('CRIA OBJETOS'!B7=""," ",CONCATENATE("set dst ",'CRIA OBJETOS'!B7))
A29: =IF('CRIA OBJETOS'!B7=""," ",CONCATENATE("set device ",'CRIA FASE 1'!B2))
A30: =IF('CRIA OBJETOS'!B7=""," ",CONCATENATE("set comment ",'CRIA FASE 1'!B2))
A31: =IF('CRIA OBJETOS'!B7=""," ",CONCATENATE("end"))
A32: =IF('CRIA OBJETOS'!B8=""," ",CONCATENATE("config router static"))
A33: =IF('CRIA OBJETOS'!B8=""," ",CONCATENATE("edit 0"))
A34: =IF('CRIA OBJETOS'!B8=""," ",CONCATENATE("set dst ",'CRIA OBJETOS'!B8))
A35: =IF('CRIA OBJETOS'!B8=""," ",CONCATENATE("set device ",'CRIA FASE 1'!B2))
A36: =IF('CRIA OBJETOS'!B8=""," ",CONCATENATE("set comment ",'CRIA FASE 1'!B2))
A37: =IF('CRIA OBJETOS'!B8=""," ",CONCATENATE("end"))
A38: =IF('CRIA OBJETOS'!B9=""," ",CONCATENATE("config router static"))
A39: =IF('CRIA OBJETOS'!B9=""," ",CONCATENATE("edit 0"))
A40: =IF('CRIA OBJETOS'!B9=""," ",CONCATENATE("set dst ",'CRIA OBJETOS'!B9))
...
